Workbook
Name Slicer_Credential_Type: #N/A
Name Slicer_Role: #N/A
Name Slicer_Department: #N/A
Name Employee_id_range: feature_engineering!$A$2:$A$5001
Name Credential_Status_Range: feature_engineering!$H$2:$H$5001

Sheet main
A1: Employee_ID | B1: Employee_Name | C1: Department | D1: Role | E1: Credential_Type | F1: Issue_Date | G1: Expiry_Date | H1: Credential_Status
A2: 10001 | B2: Rahul 755 | C2: HR | D2: Manager | E2: System Access | F2: 45155 | G2: 45335 | H2: Expired
A3: 10002 | B3: Rahul 33 | C3: Compliance | D3: Administrator | E3: ID Card | F3: 45531 | G3: 45896 | H3: Expired
A4: 10003 | B4: Amit 28 | C4: HR | D4: Analyst | E4: System Access | F4: 45444 | G4: 46174 | H4: Active
A5: 10004 | B5: Ravi 604 | C5: IT | D5: Administrator | E5: Compliance Certificate | F5: 45152 | G5: 45517 | H5: Expired
A6: 10005 | B6: Anil 160 | C6: HR | D6: Analyst | E6: Compliance Certificate | F6: 45275 | G6: 45640 | H6: Expired
A7: 10006 | B7: Neha 368 | C7: Finance | D7: Executive | E7: ID Card | F7: 45316 | G7: 45496 | H7: Expired
A8: 10007 | B8: Kiran 128 | C8: Sales | D8: Manager | E8: ID Card | F8: 45397 | G8: 46127 | H8: Active
A9: 10008 | B9: Suresh 907 | C9: HR | D9: Administrator | E9: Safety Training | F9: 45570 | G9: 46300 | H9: Active
A10: 10009 | B10: Kiran 234 | C10: Sales | D10: Analyst | E10: ID Card | F10: 44973 | G10: 45703 | H10: Expired
A11: 10010 | B11: Anil 465 | C11: HR | D11: Analyst | E11: ID Card | F11: 45316 | G11: 45681 | H11: Expired
A12: 10011 | B12: Kiran 274 | C12: IT | D12: Manager | E12: Safety Training | F12: 45141 | G12: 45871 | H12: Expired
A13: 10012 | B13: Rahul 474 | C13: Sales | D13: Analyst | E13: NDA | F13: 45177 | G13: 45357 | H13: Expired
... A5001: 15000 | B5001: Ravi 308 | C5001: Sales | D5001: Analyst | E5001: Safety Training | F5001: 45383 | G5001: 45563 | H5001: Expired

Sheet feature_engineering
A1: Employee_ID | B1: Employee_Name | C1: Department | D1: Role | E1: Credential_Type | F1: Issue_Date | G1: Expiry_Date | H1: Credential_Status | I1: Expire_year | J1: Expire_month | K1: Days_To_Expire
A2: 10001 | B2: Rahul 755 | C2: HR | D2: Manager | E2: System Access | F2: 45155 | G2: 45335 | H2: =IF(K2<=0,"Expired",IF(AND(K2>=1,K2<=30),"Expiring_Soon","Active")) -> Expired | I2: =YEAR(G2) -> 2024 | J2: =TEXT(G2,"mmmm") -> February | K2: =G2-TODAY() -> -958
A3: 10002 | B3: Rahul 33 | C3: Compliance | D3: Administrator | E3: ID Card | F3: 45531 | G3: 45896 | H3: =IF(K3<=0,"Expired",IF(AND(K3>=1,K3<=30),"Expiring_Soon","Active")) -> Expired | I3: =YEAR(G3) -> 2025 | J3: =TEXT(G3,"mmmm") -> August | K3: =G3-TODAY() -> -397
A4: 10003 | B4: Amit 28 | C4: HR | D4: Analyst | E4: System Access | F4: 45444 | G4: 46174 | H4: =IF(K4<=0,"Expired",IF(AND(K4>=1,K4<=30),"Expiring_Soon","Active")) -> Expired | I4: =YEAR(G4) -> 2026 | J4: =TEXT(G4,"mmmm") -> June | K4: =G4-TODAY() -> -119
A5: 10004 | B5: Ravi 604 | C5: IT | D5: Administrator | E5: Compliance Certificate | F5: 45152 | G5: 45517 | H5: =IF(K5<=0,"Expired",IF(AND(K5>=1,K5<=30),"Expiring_Soon","Active")) -> Expired | I5: =YEAR(G5) -> 2024 | J5: =TEXT(G5,"mmmm") -> August | K5: =G5-TODAY() -> -776
A6: 10005 | B6: Anil 160 | C6: HR | D6: Analyst | E6: Compliance Certificate | F6: 45275 | G6: 45640 | H6: =IF(K6<=0,"Expired",IF(AND(K6>=1,K6<=30),"Expiring_Soon","Active")) -> Expired | I6: =YEAR(G6) -> 2024 | J6: =TEXT(G6,"mmmm") -> December | K6: =G6-TODAY() -> -653
A7: 10006 | B7: Neha 368 | C7: Finance | D7: Executive | E7: ID Card | F7: 45316 | G7: 45496 | H7: =IF(K7<=0,"Expired",IF(AND(K7>=1,K7<=30),"Expiring_Soon","Active")) -> Expired | I7: =YEAR(G7) -> 2024 | J7: =TEXT(G7,"mmmm") -> July | K7: =G7-TODAY() -> -797
A8: 10007 | B8: Kiran 128 | C8: Sales | D8: Manager | E8: ID Card | F8: 45397 | G8: 46127 | H8: =IF(K8<=0,"Expired",IF(AND(K8>=1,K8<=30),"Expiring_Soon","Active")) -> Expired | I8: =YEAR(G8) -> 2026 | J8: =TEXT(G8,"mmmm") -> April | K8: =G8-TODAY() -> -166
A9: 10008 | B9: Suresh 907 | C9: HR | D9: Administrator | E9: Safety Training | F9: 45570 | G9: 46300 | H9: =IF(K9<=0,"Expired",IF(AND(K9>=1,K9<=30),"Expiring_Soon","Active")) -> Expiring_Soon | I9: =YEAR(G9) -> 2026 | J9: =TEXT(G9,"mmmm") -> October | K9: =G9-TODAY() -> 7
A10: 10009 | B10: Kiran 234 | C10: Sales | D10: Analyst | E10: ID Card | F10: 44973 | G10: 45703 | H10: =IF(K10<=0,"Expired",IF(AND(K10>=1,K10<=30),"Expiring_Soon","Active")) -> Expired | I10: =YEAR(G10) -> 2025 | J10: =TEXT(G10,"mmmm") -> February | K10: =G10-TODAY() -> -590
A11: 10010 | B11: Anil 465 | C11: HR | D11: Analyst | E11: ID Card | F11: 45316 | G11: 45681 | H11: =IF(K11<=0,"Expired",IF(AND(K11>=1,K11<=30),"Expiring_Soon","Active")) -> Expired | I11: =YEAR(G11) -> 2025 | J11: =TEXT(G11,"mmmm") -> January | K11: =G11-TODAY() -> -612
A12: 10011 | B12: Kiran 274 | C12: IT | D12: Manager | E12: Safety Training | F12: 45141 | G12: 45871 | H12: =IF(K12<=0,"Expired",IF(AND(K12>=1,K12<=30),"Expiring_Soon","Active")) -> Expired | I12: =YEAR(G12) -> 2025 | J12: =TEXT(G12,"mmmm") -> August | K12: =G12-TODAY() -> -422
A13: 10012 | B13: Rahul 474 | C13: Sales | D13: Analyst | E13: NDA | F13: 45177 | G13: 45357 | H13: =IF(K13<=0,"Expired",IF(AND(K13>=1,K13<=30),"Expiring_Soon","Active")) -> Expired | I13: =YEAR(G13) -> 2024 | J13: =TEXT(G13,"mmmm") -> March | K13: =G13-TODAY() -> -936
... A5001: 15000 | B5001: Ravi 308 | C5001: Sales | D5001: Analyst | E5001: Safety Training | F5001: 45383 | G5001: 45563 | H5001: =IF(K5001<=0,"Expired",IF(AND(K5001>=1,K5001<=30),"Expiring_Soon","Active")) -> Expired | I5001: =YEAR(G5001) -> 2024 | J5001: =TEXT(G5001,"mmmm") -> September | K5001: =G5001-TODAY() -> -730

Sheet kpi
A1: Total_Credentials | B1: =COUNT(Employee_id_range) -> 5000
A2: Total_Active | B2: {=COUNTIF(Credential_Status_Range,"Active")} -> 93
A3: Total_Expired | B3: {=COUNTIF(Credential_Status_Range,"Expired")} -> 4837
A4: Total_Critical_Risk(Expiring_Soon) | B4: {=COUNTIF(Credential_Status_Range,"Expiring_Soon")} -> 70

Sheet index_and_match
H2: CREDENTIAL _STATUS_GENERATOR
H5: Select Employee ID : | I5: 14901
H7: Credential Status : | I7: {=INDEX(feature_engineering!H2:H5001,MATCH(I5,feature_engineering!A2:A5001,0))} -> Expiring_Soon

Sheet lookup
A1: V LOOKUP
A3: employee_id | B3: Department | C3: Role | D3: Credential_Type
A4: 10008 | B4: =IFERROR(VLOOKUP(A4,feature_engineering!A$1:K$5001,3,0),"N/A") -> HR | C4: =IFERROR(VLOOKUP(A4,feature_engineering!A$1:K$5001,4,0),"N/A") -> Administrator | D4: =IFERROR(VLOOKUP(A4,feature_engineering!A$1:K$5001,5,0),"N/A") -> Safety Training
A5: 10017 | B5: =IFERROR(VLOOKUP(A5,feature_engineering!A$1:K$5001,3,0),"N/A") -> Finance | C5: =IFERROR(VLOOKUP(A5,feature_engineering!A$1:K$5001,4,0),"N/A") -> Administrator | D5: =IFERROR(VLOOKUP(A5,feature_engineering!A$1:K$5001,5,0),"N/A") -> Compliance Certificate
A6: 10026 | B6: =IFERROR(VLOOKUP(A6,feature_engineering!A$1:K$5001,3,0),"N/A") -> Finance | C6: =IFERROR(VLOOKUP(A6,feature_engineering!A$1:K$5001,4,0),"N/A") -> Analyst | D6: =IFERROR(VLOOKUP(A6,feature_engineering!A$1:K$5001,5,0),"N/A") -> ID Card
A7: 10045 | B7: =IFERROR(VLOOKUP(A7,feature_engineering!A$1:K$5001,3,0),"N/A") -> Operations | C7: =IFERROR(VLOOKUP(A7,feature_engineering!A$1:K$5001,4,0),"N/A") -> Administrator | D7: =IFERROR(VLOOKUP(A7,feature_engineering!A$1:K$5001,5,0),"N/A") -> NDA
A8: 10074 | B8: =IFERROR(VLOOKUP(A8,feature_engineering!A$1:K$5001,3,0),"N/A") -> Compliance | C8: =IFERROR(VLOOKUP(A8,feature_engineering!A$1:K$5001,4,0),"N/A") -> Analyst | D8: =IFERROR(VLOOKUP(A8,feature_engineering!A$1:K$5001,5,0),"N/A") -> Safety Training
A9: 123 | B9: =IFERROR(VLOOKUP(A9,feature_engineering!A$1:K$5001,3,0),"N/A") -> N/A | C9: =IFERROR(VLOOKUP(A9,feature_engineering!A$1:K$5001,4,0),"N/A") -> N/A | D9: =IFERROR(VLOOKUP(A9,feature_engineering!A$1:K$5001,5,0),"N/A") -> N/A
A14: X LOOKUP
A16: employee_id | B16: Department | C16: Role | D16: Credential_Type
A17: 14959 | B17: =_xlfn.XLOOKUP(A17,feature_engineering!A$2:A$5001,feature_engineering!C$2:C$5001,"NOT FOUND",0) -> Finance | C17: =_xlfn.XLOOKUP(A17,feature_engineering!A$2:A$5001,feature_engineering!D$2:D$5001,"NOT FOUND",0) -> Executive | D17: =_xlfn.XLOOKUP(A17,feature_engineering!A$2:A$5001,feature_engineering!E$2:E$5001,"NOT FOUND",0) -> NDA
A18: 10022 | B18: =_xlfn.XLOOKUP(A18,feature_engineering!A$2:A$5001,feature_engineering!C$2:C$5001,"NOT FOUND",0) -> Finance | C18: =_xlfn.XLOOKUP(A18,feature_engineering!A$2:A$5001,feature_engineering!D$2:D$5001,"NOT FOUND",0) -> Lead | D18: =_xlfn.XLOOKUP(A18,feature_engineering!A$2:A$5001,feature_engineering!E$2:E$5001,"NOT FOUND",0) -> System Access
A19: 10078 | B19: =_xlfn.XLOOKUP(A19,feature_engineering!A$2:A$5001,feature_engineering!C$2:C$5001,"NOT FOUND",0) -> Sales | C19: =_xlfn.XLOOKUP(A19,feature_engineering!A$2:A$5001,feature_engineering!D$2:D$5001,"NOT FOUND",0) -> Executive | D19: =_xlfn.XLOOKUP(A19,feature_engineering!A$2:A$5001,feature_engineering!E$2:E$5001,"NOT FOUND",0) -> Safety Training
A20: 14998 | B20: =_xlfn.XLOOKUP(A20,feature_engineering!A$2:A$5001,feature_engineering!C$2:C$5001,"NOT FOUND",0) -> Operations | C20: =_xlfn.XLOOKUP(A20,feature_engineering!A$2:A$5001,feature_engineering!D$2:D$5001,"NOT FOUND",0) -> Manager | D20: =_xlfn.XLOOKUP(A20,feature_engineering!A$2:A$5001,feature_engineering!E$2:E$5001,"NOT FOUND",0) -> Safety Training

Sheet pivot_table
A1: Count of Credential_Status | B1: Credential_Status
A2: Department | B2: Active | C2: Expired | D2: Expiring_Soon | E2: Grand Total
A3: Compliance | B3: 14 | C3: 794 | D3: 16 | E3: 824
A4: Finance | B4: 14 | C4: 780 | D4: 9 | E4: 803
A5: HR | B5: 12 | C5: 789 | D5: 17 | E5: 818
A6: IT | B6: 13 | C6: 813 | D6: 13 | E6: 839
A7: Operations | B7: 17 | C7: 834 | D7: 15 | E7: 866
A8: Sales | B8: 25 | C8: 817 | D8: 8 | E8: 850
A9: Grand Total | B9: 95 | C9: 4827 | D9: 78 | E9: 5000
A13: Credential_Status | B13: Expired
A15: Credential_Type | B15: Count of Credential_Type
A16: Compliance Certificate | B16: 1001
A17: ID Card | B17: 981
A18: NDA | B18: 974
A19: Safety Training | B19: 960
A20: System Access | B20: 911
A21: Grand Total | B21: 4827
A25: Credential_Status | B25: Active
A27: Role | B27: Count of Role
A28: Administrator | B28: 18
A29: Analyst | B29: 24
A30: Executive | B30: 14
A31: Lead | B31: 22
A32: Manager | B32: 17
A33: Grand Total | B33: 95
A39: Credential_Status | B39: Expiring_Soon
A41: Employee_Name | B41: Department | C41: Credential_Type | D41: Expiry_Date
A42: Amit 299
B43: IT
C44: Safety Training
D45: 46300
A46: Amit 33
B47: IT
C48: NDA
D49: 46301
A50: Amit 438
B51: Sales
C52: System Access
D53: 46298
A54: Amit 571
...

Sheet pivot_chart
A3: Credential_Status | B3: Count of Credential_Status
A4: Active | B4: 95
A5: Expired | B5: 4827
A6: Expiring_Soon | B6: 78
A7: Grand Total | B7: 5000
A23: Credential_Status | B23: Expired
A25: Credential_Type | B25: Count of Credential_Type
A26: Compliance Certificate | B26: 1001
A27: ID Card | B27: 981
A28: NDA | B28: 974
A29: Safety Training | B29: 960
A30: System Access | B30: 911
A31: Grand Total | B31: 4827
A42: Credential_Status | B42: Count of Credential_Status
A43: Active | B43: 95
A44: Expired | B44: 4827
A45: Expiring_Soon | B45: 78
A46: Grand Total | B46: 5000

Sheet KPI_DASHBOARD
